Workbook

Sheet Analysis
A1: Recording Academy - Website Performance Analysis
A2: Analyzing the impact of splitting grammy.com and recordingacademy.com | Tools: Excel · PivotTables · XLOOKUP · SUMIF · AVERAGEIF · A/B Testing
A4: Overview
A6: In February 2022, The Recording Academy - the non-profit behind the Grammy Awards - split their single website into two domains: grammy.com for the awards show and fan audience, and recordingacademy.com for their industry and professional community. This analysis examines whether that decision improved user engagement using real web traffic data spanning 2017-2023.
A10: 1. Traffic Analysis
A31: Finding: The line chart shows that grammy.com traffic follows a clear seasonal pattern - traffic runs at a steady baseline throughout the year but spikes dramatically every January/February during the Grammy Awards ceremony. Awards night generates 43x more visitors than a normal day (1,389,590 vs 32,388). Smaller secondary spikes around November/December correspond to Grammy nominee announcements. | F31: Row Labels | G31: Average of visitors
F32: Grammy Awards | G32: 1389590.2
F33: Regular Day | G33: 32388.277
F34: Difference (x) | G34: =GETPIVOTDATA("visitors",$F$31,"event_type","Grammy Awards") / GETPIVOTDATA("visitors",$F$31,"event_type","Regular Day") -> 42.904111
A37: 2. Engagement KPIs
A39: The table below compares user engagement across three periods: the combined site (before Feb 2022), grammy.com (after split), and recordingacademy.com (after split).
A42: Site | B42: Pages per Session | C42: Bounce Rate | D42: Avg Time on Site (secs)
A43: Combined Site (pre-split) | B43: =SUMIF(Grammys[website_content], "Grammys + TRA", Grammys[pageviews]) / SUMIF(Grammys[website_content], "Grammys + TRA", Grammys[sessions]) -> 1.8606084 | C43: =SUMIF(Grammys[website_content], "Grammys + TRA", Grammys[bounced_sessions]) / SUMIF(Grammys[website_content], "Grammys + TRA", Grammys[sessions]) -> 0.41584428 | D43: =AVERAGEIF(Grammys[website_content], "Grammys + TRA", Grammys[avg_session_duration_secs]) -> 102.85353
A44: grammy.com (post-split) | B44: =SUMIF(Grammys[website_content], "Grammys", Grammys[pageviews]) / SUMIF(Grammys[website_content], "Grammys", Grammys[sessions]) -> 2.2532667 | C44: =SUMIF(Grammys[website_content], "Grammys", Grammys[bounced_sessions]) / SUMIF(Grammys[website_content], "Grammys", Grammys[sessions]) -> 0.40158614 | D44: =AVERAGEIF(Grammys[website_content], "Grammys", Grammys[avg_session_duration_secs]) -> 82.985567
A45: recordingacademy.com (post-split) | B45: =SUM(TRA[pageviews]) / SUM(TRA[sessions]) -> 2.7792846 | C45: =SUM(TRA[bounced_sessions]) / SUM(TRA[sessions]) -> 0.33671924 | D45: =AVERAGE(TRA[avg_session_duration_secs]) -> 128.50309
A47: Finding: All three engagement metrics improved after the website split. recordingacademy.com outperforms on every KPI - its bounce rate dropped to 33.7% (vs 41.6% combined), pages per session increased to 2.78 (vs 1.86 combined), and average time on site rose to 128.50 seconds (vs 102.85 combined). This confirms the split successfully created more focused, engaging experiences for each audience. Among the three metrics, average time on site showed the biggest improvement - rising from 102.85 to 128.50 seconds after the split.
A53: 3. Device Breakdown
A55: Device | B55: % of Visitors
A56: Mobile | B56: =SUMIF(Grammys[website_content],"Grammys",Grammys[mobile_visitors])/SUMIF(Grammys[website_content],"Grammys",Grammys[visitors]) -> 0.73692175
A57: Desktop | B57: =1 - B56 -> 0.26307825
A59: Finding: 73.7% of grammy.com visitors access the site via mobile devices, compared to only 26.3% on desktop. This heavy mobile skew is important context for the engagement metrics - mobile users typically have higher bounce rates and shorter session times due to smaller screens and slower load times. This means grammy.com's actual desktop engagement is likely stronger than the overall averages suggest.
A64: 4. Recommendation
A66: The data strongly supports keeping the two websites separate. All three engagement metrics - pages per session, bounce rate, and average time on site - improved after the split. recordingacademy.com in particular shows significantly better engagement, confirming that separating the professional audience from the fan audience was the right decision. However, two areas need attention: 1. Seasonality: grammy.com relies almost entirely on the annual awards show, which drives 43x more traffic than a normal day. Investing in year-round content such as artist spotlights, music history, and exclusive features would help maintain traffic between events. 2. Mobile Optimization: With 73.7% of visitors on mobile, the mobile experience must be a top priority. Improving page load times, navigation, and mobile-friendly layouts could directly reduce the bounce rate and increase time on site.

Sheet Grammys Data
A1: date | B1: visitors | C1: pageviews | D1: sessions | E1: bounced_sessions | F1: avg_session_duration_secs | G1: event_type | H1: website_content | I1: mobile_visitors | Q1: date | R1: mobile_visitors
A2: 42736 | B2: 9611 | C2: 21407 | D2: 10196 | E2: 6490 | F2: 86 | G2: Regular Day | H2: =IF(Grammys[[#This Row],[date]] >= DATE(2022, 2, 1), "Grammys", "Grammys + TRA") -> Grammys + TRA | I2: =_xlfn.XLOOKUP(Grammys[[#This Row],[date]], mobile_visits[date], mobile_visits[mobile_visitors], 0) -> 0 | K2: Formulas Used: website_content: = IF([@date] >= DATE(2022,2,1), "Grammys", "Grammys + TRA") mobile_visitors: = XLOOKUP([@date], mobile_visits[date], mobile_visits[mobile_visitors], 0) | Q2: 44593 | R2: 23014
A3: 42737 | B3: 10752 | C3: 25658 | D3: 11350 | E3: 7055 | F3: 100 | G3: Regular Day | H3: =IF(Grammys[[#This Row],[date]] >= DATE(2022, 2, 1), "Grammys", "Grammys + TRA") -> Grammys + TRA | I3: =_xlfn.XLOOKUP(Grammys[[#This Row],[date]], mobile_visits[date], mobile_visits[mobile_visitors], 0) -> 0 | Q3: 44594 | R3: 19951
A4: 42738 | B4: 11425 | C4: 27062 | D4: 12215 | E4: 7569 | F4: 92 | G4: Regular Day | H4: =IF(Grammys[[#This Row],[date]] >= DATE(2022, 2, 1), "Grammys", "Grammys + TRA") -> Grammys + TRA | I4: =_xlfn.XLOOKUP(Grammys[[#This Row],[date]], mobile_visits[date], mobile_visits[mobile_visitors], 0) -> 0 | Q4: 44595 | R4: 21567
A5: 42739 | B5: 13098 | C5: 29189 | D5: 13852 | E5: 8929 | F5: 90 | G5: Regular Day | H5: =IF(Grammys[[#This Row],[date]] >= DATE(2022, 2, 1), "Grammys", "Grammys + TRA") -> Grammys + TRA | I5: =_xlfn.XLOOKUP(Grammys[[#This Row],[date]], mobile_visits[date], mobile_visits[mobile_visitors], 0) -> 0 | Q5: 44596 | R5: 18362
A6: 42740 | B6: 12234 | C6: 28288 | D6: 12990 | E6: 8105 | F6: 95 | G6: Regular Day | H6: =IF(Grammys[[#This Row],[date]] >= DATE(2022, 2, 1), "Grammys", "Grammys + TRA") -> Grammys + TRA | I6: =_xlfn.XLOOKUP(Grammys[[#This Row],[date]], mobile_visits[date], mobile_visits[mobile_visitors], 0) -> 0 | Q6: 44597 | R6: 12590
A7: 42741 | B7: 11461 | C7: 28022 | D7: 12309 | E7: 7500 | F7: 95 | G7: Regular Day | H7: =IF(Grammys[[#This Row],[date]] >= DATE(2022, 2, 1), "Grammys", "Grammys + TRA") -> Grammys + TRA | I7: =_xlfn.XLOOKUP(Grammys[[#This Row],[date]], mobile_visits[date], mobile_visits[mobile_visitors], 0) -> 0 | Q7: 44598 | R7: 12316
A8: 42742 | B8: 11183 | C8: 27491 | D8: 11993 | E8: 7287 | F8: 94 | G8: Regular Day | H8: =IF(Grammys[[#This Row],[date]] >= DATE(2022, 2, 1), "Grammys", "Grammys + TRA") -> Grammys + TRA | I8: =_xlfn.XLOOKUP(Grammys[[#This Row],[date]], mobile_visits[date], mobile_visits[mobile_visitors], 0) -> 0 | Q8: 44599 | R8: 10416
A9: 42743 | B9: 16265 | C9: 38529 | D9: 17361 | E9: 10587 | F9: 84 | G9: Regular Day | H9: =IF(Grammys[[#This Row],[date]] >= DATE(2022, 2, 1), "Grammys", "Grammys + TRA") -> Grammys + TRA | I9: =_xlfn.XLOOKUP(Grammys[[#This Row],[date]], mobile_visits[date], mobile_visits[mobile_visitors], 0) -> 0 | K9: Formula Notes: DATE(2022, 2, 1) is used because February 1st, 2022 is the exact date The Recording Academy split into two separate domains. Dates before this are labeled "Grammys + TRA" (combined site) and dates on or after are labeled "Grammys" (post-split). XLOOKUP matches each date to the mobile_visits table to fill in mobile visitor counts, returning 0 if no data exists for that date. | Q9: 44600 | R9: 19299
A10: 42744 | B10: 17852 | C10: 40698 | D10: 18914 | E10: 11697 | F10: 87 | G10: Regular Day | H10: =IF(Grammys[[#This Row],[date]] >= DATE(2022, 2, 1), "Grammys", "Grammys + TRA") -> Grammys + TRA | I10: =_xlfn.XLOOKUP(Grammys[[#This Row],[date]], mobile_visits[date], mobile_visits[mobile_visitors], 0) -> 0 | Q10: 44601 | R10: 16050
A11: 42745 | B11: 14211 | C11: 33218 | D11: 15124 | E11: 9270 | F11: 96 | G11: Regular Day | H11: =IF(Grammys[[#This Row],[date]] >= DATE(2022, 2, 1), "Grammys", "Grammys + TRA") -> Grammys + TRA | I11: =_xlfn.XLOOKUP(Grammys[[#This Row],[date]], mobile_visits[date], mobile_visits[mobile_visitors], 0) -> 0 | Q11: 44602 | R11: 13590
A12: 42746 | B12: 13456 | C12: 30704 | D12: 14397 | E12: 8922 | F12: 99 | G12: Regular Day | H12: =IF(Grammys[[#This Row],[date]] >= DATE(2022, 2, 1), "Grammys", "Grammys + TRA") -> Grammys + TRA | I12: =_xlfn.XLOOKUP(Grammys[[#This Row],[date]], mobile_visits[date], mobile_visits[mobile_visitors], 0) -> 0 | Q12: 44603 | R12: 13393
A13: 42747 | B13: 13616 | C13: 31559 | D13: 14613 | E13: 9227 | F13: 98 | G13: Regular Day | H13: =IF(Grammys[[#This Row],[date]] >= DATE(2022, 2, 1), "Grammys", "Grammys + TRA") -> Grammys + TRA | I13: =_xlfn.XLOOKUP(Grammys[[#This Row],[date]], mobile_visits[date], mobile_visits[mobile_visitors], 0) -> 0 | Q13: 44604 | R13: 13824
A14: 42748 | B14: 11880 | C14: 27526 | D14: 12805 | E14: 8148 | F14: 97 | G14: Regular Day | H14: =IF(Grammys[[#This Row],[date]] >= DATE(2022, 2, 1), "Grammys", "Grammys + TRA") -> Grammys + TRA | I14: =_xlfn.XLOOKUP(Grammys[[#This Row],[date]], mobile_visits[date], mobile_visits[mobile_visitors], 0) -> 0 | Q14: 44605 | R14: 15704
A15: 42749 | B15: 11888 | C15: 27940 | D15: 12608 | E15: 7804 | F15: 93 | G15: Regular Day | H15: =IF(Grammys[[#This Row],[date]] >= DATE(2022, 2, 1), "Grammys", "Grammys + TRA") -> Grammys + TRA | I15: =_xlfn.XLOOKUP(Grammys[[#This Row],[date]], mobile_visits[date], mobile_visits[mobile_visitors], 0) -> 0 | Q15: 44606 | R15: 9362
A16: 42750 | B16: 12706 | C16: 29109 | D16: 13416 | E16: 8349 | F16: 96 | G16: Regular Day | H16: =IF(Grammys[[#This Row],[date]] >= DATE(2022, 2, 1), "Grammys", "Grammys + TRA") -> Grammys + TRA | I16: =_xlfn.XLOOKUP(Grammys[[#This Row],[date]], mobile_visits[date], mobile_visits[mobile_visitors], 0) -> 0 | Q16: 44607 | R16: 9596
A17: 42751 | B17: 12691 | C17: 30284 | D17: 13525 | E17: 8282 | F17: 100 | G17: Regular Day | H17: =IF(Grammys[[#This Row],[date]] >= DATE(2022, 2, 1), "Grammys", "Grammys + TRA") -> Grammys + TRA | I17: =_xlfn.XLOOKUP(Grammys[[#This Row],[date]], mobile_visits[date], mobile_visits[mobile_visitors], 0) -> 0 | Q17: 44608 | R17: 11132
A18: 42752 | B18: 13260 | C18: 33596 | D18: 14260 | E18: 8514 | F18: 121 | G18: Regular Day | H18: =IF(Grammys[[#This Row],[date]] >= DATE(2022, 2, 1), "Grammys", "Grammys + TRA") -> Grammys + TRA | I18: =_xlfn.XLOOKUP(Grammys[[#This Row],[date]], mobile_visits[date], mobile_visits[mobile_visitors], 0) -> 0 | Q18: 44609 | R18: 10821
A19: 42753 | B19: 14483 | C19: 36586 | D19: 15809 | E19: 9494 | F19: 117 | G19: Regular Day | H19: =IF(Grammys[[#This Row],[date]] >= DATE(2022, 2, 1), "Grammys", "Grammys + TRA") -> Grammys + TRA | I19: =_xlfn.XLOOKUP(Grammys[[#This Row],[date]], mobile_visits[date], mobile_visits[mobile_visitors], 0) -> 0 | Q19: 44610 | R19: 8344
A20: 42754 | B20: 13551 | C20: 31964 | D20: 14694 | E20: 9118 | F20: 104 | G20: Regular Day | H20: =IF(Grammys[[#This Row],[date]] >= DATE(2022, 2, 1), "Grammys", "Grammys + TRA") -> Grammys + TRA | I20: =_xlfn.XLOOKUP(Grammys[[#This Row],[date]], mobile_visits[date], mobile_visits[mobile_visitors], 0) -> 0 | Q20: 44611 | R20: 9054
A21: 42755 | B21: 13215 | C21: 32339 | D21: 14083 | E21: 8609 | F21: 99 | G21: Regular Day | H21: =IF(Grammys[[#This Row],[date]] >= DATE(2022, 2, 1), "Grammys", "Grammys + TRA") -> Grammys + TRA | I21: =_xlfn.XLOOKUP(Grammys[[#This Row],[date]], mobile_visits[date], mobile_visits[mobile_visitors], 0) -> 0 | Q21: 44612 | R21: 10781
... A516: 43250 | B516: 14774 | C516: 20555 | D516: 14911 | E516: 7695 | F516: 274 | G516: Regular Day | H516: =IF(Grammys[[#This Row],[date]] >= DATE(2022, 2, 1), "Grammys", "Grammys + TRA") -> Grammys + TRA | I516: =_xlfn.XLOOKUP(Grammys[[#This Row],[date]], mobile_visits[date], mobile_visits[mobile_visitors], 0) -> 0 | Q516: 45107 | R516: 14446
A517: 43251 | B517: 13053 | C517: 17758 | D517: 13211 | E517: 6417 | F517: 242 | G517: Regular Day | H517: =IF(Grammys[[#This Row],[date]] >= DATE(2022, 2, 1), "Grammys", "Grammys + TRA") -> Grammys + TRA | I517: =_xlfn.XLOOKUP(Grammys[[#This Row],[date]], mobile_visits[date], mobile_visits[mobile_visitors], 0) -> 0
A518: 43252 | B518: 11825 | C518: 16289 | D518: 11767 | E518: 6072 | F518: 265 | G518: Regular Day | H518: =IF(Grammys[[#This Row],[date]] >= DATE(2022, 2, 1), "Grammys", "Grammys + TRA") -> Grammys + TRA | I518: =_xlfn.XLOOKUP(Grammys[[#This Row],[date]], mobile_visits[date], mobile_visits[mobile_visitors], 0) -> 0
A519: 43253 | B519: 9932 | C519: 13248 | D519: 9881 | E519: 5747 | F519: 213 | G519: Regular Day | H519: =IF(Grammys[[#This Row],[date]] >= DATE(2022, 2, 1), "Grammys", "Grammys + TRA") -> Grammys + TRA | I519: =_xlfn.XLOOKUP(Grammys[[#This Row],[date]], mobile_visits[date], mobile_visits[mobile_visitors], 0) -> 0
A520: 43254 | B520: 9586 | C520: 13226 | D520: 9530 | E520: 5468 | F520: 254 | G520: Regular Day | H520: =IF(Grammys[[#This Row],[date]] >= DATE(2022, 2, 1), "Grammys", "Grammys + TRA") -> Grammys + TRA | I520: =_xlfn.XLOOKUP(Grammys[[#This Row],[date]], mobile_visits[date], mobile_visits[mobile_visitors], 0) -> 0
A521: 43255 | B521: 10093 | C521: 14899 | D521: 10245 | E521: 5846 | F521: 324 | G521: Regular Day | H521: =IF(Grammys[[#This Row],[date]] >= DATE(2022, 2, 1), "Grammys", "Grammys + TRA") -> Grammys + TRA | I521: =_xlfn.XLOOKUP(Grammys[[#This Row],[date]], mobile_visits[date], mobile_visits[mobile_visitors], 0) -> 0
A522: 43256 | B522: 10463 | C522: 14842 | D522: 10405 | E522: 5965 | F522: 279 | G522: Regular Day | H522: =IF(Grammys[[#This Row],[date]] >= DATE(2022, 2, 1), "Grammys", "Grammys + TRA") -> Grammys + TRA | I522: =_xlfn.XLOOKUP(Grammys[[#This Row],[date]], mobile_visits[date], mobile_visits[mobile_visitors], 0) -> 0
A523: 43257 | B523: 11449 | C523: 15810 | D523: 11504 | E523: 6819 | F523: 237 | G523: Regular Day | H523: =IF(Grammys[[#This Row],[date]] >= DATE(2022, 2, 1), "Grammys", "Grammys + TRA") -> Grammys + TRA | I523: =_xlfn.XLOOKUP(Grammys[[#This Row],[date]], mobile_visits[date], mobile_visits[mobile_visitors], 0) -> 0
A524: 43258 | B524: 10669 | C524: 15170 | D524: 10796 | E524: 6249 | F524: 255 | G524: Regular Day | H524: =IF(Grammys[[#This Row],[date]] >= DATE(2022, 2, 1), "Grammys", "Grammys + TRA") -> Grammys + TRA | I524: =_xlfn.XLOOKUP(Grammys[[#This Row],[date]], mobile_visits[date], mobile_visits[mobile_visitors], 0) -> 0
A525: 43259 | B525: 10215 | C525: 14300 | D525: 10250 | E525: 5891 | F525: 267 | G525: Regular Day | H525: =IF(Grammys[[#This Row],[date]] >= DATE(2022, 2, 1), "Grammys", "Grammys + TRA") -> Grammys + TRA | I525: =_xlfn.XLOOKUP(Grammys[[#This Row],[date]], mobile_visits[date], mobile_visits[mobile_visitors], 0) -> 0
A526: 43260 | B526: 21010 | C526: 27986 | D526: 21659 | E526: 8835 | F526: 279 | G526: Regular Day | H526: =IF(Grammys[[#This Row],[date]] >= DATE(2022, 2, 1), "Grammys", "Grammys + TRA") -> Grammys + TRA | I526: =_xlfn.XLOOKUP(Grammys[[#This Row],[date]], mobile_visits[date], mobile_visits[mobile_visitors], 0) -> 0
A527: 43261 | B527: 14918 | C527: 20506 | D527: 15207 | E527: 7698 | F527: 306 | G527: Regular Day | H527: =IF(Grammys[[#This Row],[date]] >= DATE(2022, 2, 1), "Grammys", "Grammys + TRA") -> Grammys + TRA | I527: =_xlfn.XLOOKUP(Grammys[[#This Row],[date]], mobile_visits[date], mobile_visits[mobile_visitors], 0) -> 0
A528: 43262 | B528: 22842 | C528: 30176 | D528: 23244 | E528: 9366 | F528: 264 | G528: Regular Day | H528: =IF(Grammys[[#This Row],[date]] >= DATE(2022, 2, 1), "Grammys", "Grammys + TRA") -> Grammys + TRA | I528: =_xlfn.XLOOKUP(Grammys[[#This Row],[date]], mobile_visits[date], mobile_visits[mobile_visitors], 0) -> 0
... A2343: 45077 | B2343: 31253 | C2343: 85686 | D2343: 33237 | E2343: 8200 | F2343: 106 | G2343: Regular Day | H2343: =IF(Grammys[[#This Row],[date]] >= DATE(2022, 2, 1), "Grammys", "Grammys + TRA") -> Grammys | I2343: =_xlfn.XLOOKUP(Grammys[[#This Row],[date]], mobile_visits[date], mobile_visits[mobile_visitors], 0) -> 22726

Sheet Recording Academy Data
A1: date | B1: year | C1: visitors | D1: pageviews | E1: sessions | F1: bounced_sessions | G1: avg_session_duration_secs
A2: 44593 | B2: =YEAR(TRA[[#This Row],[date]]) -> 2022 | C2: 928 | D2: 2856 | E2: 1092 | F2: 591 | G2: 148
A3: 44594 | B3: =YEAR(TRA[[#This Row],[date]]) -> 2022 | C3: 1329 | D3: 3233 | E3: 1490 | F3: 923 | G3: 90
A4: 44595 | B4: =YEAR(TRA[[#This Row],[date]]) -> 2022 | C4: 1138 | D4: 3340 | E4: 1322 | F4: 754 | G4: 127
A5: 44596 | B5: =YEAR(TRA[[#This Row],[date]]) -> 2022 | C5: 811 | D5: 2552 | E5: 963 | F5: 534 | G5: 142
A6: 44597 | B6: =YEAR(TRA[[#This Row],[date]]) -> 2022 | C6: 541 | D6: 1530 | E6: 602 | F6: 326 | G6: 111
A7: 44598 | B7: =YEAR(TRA[[#This Row],[date]]) -> 2022 | C7: 536 | D7: 1669 | E7: 610 | F7: 339 | G7: 147
A8: 44599 | B8: =YEAR(TRA[[#This Row],[date]]) -> 2022 | C8: 921 | D8: 3512 | E8: 1117 | F8: 567 | G8: 198
A9: 44600 | B9: =YEAR(TRA[[#This Row],[date]]) -> 2022 | C9: 1106 | D9: 3662 | E9: 1296 | F9: 661 | G9: 163
A10: 44601 | B10: =YEAR(TRA[[#This Row],[date]]) -> 2022 | C10: 1181 | D10: 4209 | E10: 1382 | F10: 725 | G10: 150
A11: 44602 | B11: =YEAR(TRA[[#This Row],[date]]) -> 2022 | C11: 1134 | D11: 3473 | E11: 1341 | F11: 727 | G11: 140
A12: 44603 | B12: =YEAR(TRA[[#This Row],[date]]) -> 2022 | C12: 871 | D12: 3263 | E12: 1045 | F12: 577 | G12: 183
A13: 44604 | B13: =YEAR(TRA[[#This Row],[date]]) -> 2022 | C13: 628 | D13: 1791 | E13: 726 | F13: 418 | G13: 116
... A486: 45077 | B486: =YEAR(TRA[[#This Row],[date]]) -> 2023 | C486: 1618 | D486: 5163 | E486: 2072 | F486: 1195 | G486: 172

Sheet AB Test
A1: A/B Test - CTA Click - Through Rate Analysis | K1: website version | L1: group | M1: CTA clicked
A2: Testing whether the website split improved user engagement with the Grammy Awards highlights CTA button | K2: websites combined | L2: control | M2: 0
K3: websites combined | L3: control | M3: 0
A4: Background | K4: websites split | L4: test | M4: 0
K5: websites combined | L5: control | M5: 0
A6: The Recording Academy added a CTA (Call-to-Action) button on the homepage that read: "Click here to watch highlights from the 64th GRAMMY Awards!" An A/B test was conducted to measure whether visitors on the new split sites were more likely to click this button compared to visitors on the old combined site. | K6: websites combined | L6: control | M6: 0
K7: websites combined | L7: control | M7: 0
K8: websites combined | L8: control | M8: 0
K9: websites split | L9: test | M9: 0
K10: websites combined | L10: control | M10: 0
A11: Hypotheses | K11: websites combined | L11: control | M11: 0
K12: websites combined | L12: control | M12: 0
A13: Null Hypothesis (H₀) | C13: Splitting the website will not result in any significant difference in the CTA click-through rate compared to the old combined site. | K13: websites split | L13: test | M13: 0
K14: websites split | L14: test | M14: 0
A15: Alternative Hypothesis (H₁) | C15: Splitting the website will result in a higher CTA click-through rate compared to the old combined site. | K15: websites split | L15: test | M15: 0
K16: websites combined | L16: control | M16: 0
K17: websites combined | L17: control | M17: 0
A18: Test Setup | K18: websites split | L18: test | M18: 0
K19: websites combined | L19: control | M19: 0
A20: Control Group | C20: Test Group | K20: websites split | L20: test | M20: 0
A21: Visitors directed to the original combined Grammy + Recording Academy website. | C21: Visitors directed to the new split sites (grammy.com or recordingacademy.com). | K21: websites split | L21: test | M21: 0
K22: websites combined | L22: control | M22: 1
K23: websites combined | L23: control | M23: 0
K24: websites combined | L24: control | M24: 0
A25: Results | K25: websites split | L25: test | M25: 0
K26: websites combined | L26: control | M26: 0
A27: Count of website version | B27: Column Labels | K27: websites combined | L27: control | M27: 0
A28: Row Labels | B28: 0 | C28: 1 | D28: Conversion Rate | K28: websites split | L28: test | M28: 0
A29: control | B29: 3678 | C29: 119 | D29: =GETPIVOTDATA("website version",$A$27,"group","control","CTA clicked",1) / (GETPIVOTDATA("website version",$A$27,"group","control","CTA clicked",0) + GETPIVOTDATA("website version",$A$27,"group","control","CTA clicked",1)) -> 0.031340532 | K29: websites split | L29: test | M29: 0
A30: test | B30: 3941 | C30: 158 | D30: =GETPIVOTDATA("website version",$A$27,"group","test","CTA clicked",1) / (GETPIVOTDATA("website version",$A$27,"group","test","CTA clicked",0) + GETPIVOTDATA("website version",$A$27,"group","test","CTA clicked",1)) -> 0.038545987 | K30: websites combined | L30: control | M30: 0
K31: websites combined | L31: control | M31: 0
A32: Note: In the dataset, CTA clicked = 1 means the visitor clicked the button and CTA clicked = 0 means they did not click it. Finding: The test group (split sites) achieved a 3.85% conversion rate compared to 3.13% for the control group (combined site). The test group had 39 more CTA clicks despite only 302 more visitors. Statistical significance was verified using the Neil Patel A/B Testing Significance Calculator (neilpatel.com/ab-testing-calculator), confirming the improvement is real and not due to random chance. This confirms the website split made users more likely to engage with the Grammy highlights CTA. | K32: websites combined | L32: control | M32: 0
K33: websites combined | L33: control | M33: 0
K34: websites combined | L34: control | M34: 0
K35: websites split | L35: test | M35: 0
K36: websites split | L36: test | M36: 0
K37: websites combined | L37: control | M37: 0
K38: websites combined | L38: control | M38: 0
A39: Conclusion | K39: websites combined | L39: control | M39: 0
K40: websites combined | L40: control | M40: 0
...

Sheet Data Dictionary
A1: Data Dictionary: Grammys
A3: column name | B3: description
A4: date | B4: The date of the recorded website activity.
A5: visitors | B5: The number of unique visitors to the website on a given day.
A6: pageviews | B6: The total number of pages viewed by all visitors.
A7: sessions | B7: The total number of browsing sessions initiated by visitors.
A8: bounced_sessions | B8: The number of sessions where the user left the site without interacting.
A9: avg_session_duration_secs | B9: The average length of a session in seconds.
A10: event_type | B10: The type of event occurring on that date (e.g., Grammy Awards, nominee announcements).
A11: website_content | B11: The type of content hosted on the website that day (e.g., "Grammys" or "Grammys + TRA").
A12: mobile_visitors | B12: The number of visitors accessing the website from a mobile device.
A14: Data Dictionary: TRA
A16: column name | B16: description
A17: date | B17: The date of the recorded website activity.
A18: visitors | B18: The number of unique visitors to the website on a given day.
A19: pageviews | B19: The total number of pages viewed by all visitors.
A20: sessions | B20: The total number of browsing sessions initiated by visitors.
A21: bounced_sessions | B21: The number of sessions where the user left the site without interacting.
A22: avg_session_duration_secs | B22: The average length of a session in seconds.
A23: event_type | B23: The type of event occurring on that date (e.g., Grammy Awards, nominee announcements).
A24: website_content | B24: The type of content hosted on the website that day (e.g., "Grammys" or "Grammys + TRA").
A25: mobile_visitors | B25: The number of visitors accessing the website from a mobile device.

Sheet Solutions
A1: Question | B1: Value | C1: Tolerance | D1: student-solution | E1: student-formula
A2: 4a | B2: 2.7792846 | C2: 0.01 | D2: =IFERROR(INDEX(#REF!,1,1),"no solution") -> no solution | E2: =IFERROR(_xlfn.FORMULATEXT(INDEX(#REF!,1)),"no formula") -> no formula
A3: 4b | B3: 2.2532667 | C3: 0.01 | D3: =IFERROR(INDEX(#REF!,1,1),"no solution") -> no solution | E3: =IFERROR(_xlfn.FORMULATEXT(INDEX(#REF!,1)),"no formula") -> no formula
A4: 4c | B4: 1.8606084 | C4: 0.01 | D4: =IFERROR(INDEX(#REF!,1,1),"no solution") -> no solution | E4: =IFERROR(_xlfn.FORMULATEXT(INDEX(#REF!,1)),"no formula") -> no formula
A5: 5a | B5: 0.33671924 | C5: 0.001 | D5: =IFERROR(INDEX(#REF!,1,1),"no solution") -> no solution | E5: =IFERROR(_xlfn.FORMULATEXT(INDEX(#REF!,1)),"no formula") -> no formula
A6: 5b | B6: 0.40158614 | C6: 0.001 | D6: =IFERROR(INDEX(#REF!,1,1),"no solution") -> no solution | E6: =IFERROR(_xlfn.FORMULATEXT(INDEX(#REF!,1)),"no formula") -> no formula
A7: 5c | B7: 0.41584428 | C7: 0.001 | D7: =IFERROR(INDEX(#REF!,1,1),"no solution") -> no solution | E7: =IFERROR(_xlfn.FORMULATEXT(INDEX(#REF!,1)),"no formula") -> no formula
A8: 6a | B8: 128.50309 | C8: 0.1 | D8: =IFERROR(INDEX(#REF!,1,1),"no solution") -> no solution | E8: =IFERROR(_xlfn.FORMULATEXT(INDEX(#REF!,1)),"no formula") -> no formula
A9: 6b | B9: 82.985567 | C9: 0.1 | D9: =IFERROR(INDEX(#REF!,1,1),"no solution") -> no solution | E9: =IFERROR(_xlfn.FORMULATEXT(INDEX(#REF!,1)),"no formula") -> no formula
A10: 6c | B10: 102.85353 | C10: 0.1 | D10: =IFERROR(INDEX(#REF!,1,1),"no solution") -> no solution | E10: =IFERROR(_xlfn.FORMULATEXT(INDEX(#REF!,1)),"no formula") -> no formula
A11: 7b | B11: 0.73692175 | C11: 0.001 | D11: =IFERROR(INDEX(#REF!,1,1),"no solution") -> no solution | E11: =IFERROR(_xlfn.FORMULATEXT(INDEX(#REF!,1)),"no formula") -> no formula
A12: LevelUp4 | B12: 302 | C12: 0 | D12: =IFERROR(INDEX('AB Test'!$C$41:C$42,1,1),"no solution") -> 0 | E12: =IFERROR(_xlfn.FORMULATEXT(INDEX('AB Test'!$C$41:C$42,1)),"no formula") -> no formula
A13: LevelUp5 | B13: 39 | C13: 0 | D13: =IFERROR(INDEX('AB Test'!$C$43:C$44,1,1),"no solution") -> 0 | E13: =IFERROR(_xlfn.FORMULATEXT(INDEX('AB Test'!$C$43:C$44,1)),"no formula") -> no formula
A14: 1b | B14: free response | D14: =IF(ISBLANK(INDEX(#REF!,1,1)), "no solution", IF(ISERROR(INDEX(#REF!,1,1)), "error in parsing the solution", INDEX(#REF!,1,1))) -> error in parsing the solution
A15: 2b | D15: =IF(ISBLANK(INDEX(#REF!,1,1)), "no solution", IF(ISERROR(INDEX(#REF!,1,1)), "error in parsing the solution", INDEX(#REF!,1,1))) -> error in parsing the solution
A16: 4d | D16: =IF(ISBLANK(INDEX(#REF!,1,1)), "no solution", IF(ISERROR(INDEX(#REF!,1,1)), "error in parsing the solution", INDEX(#REF!,1,1))) -> error in parsing the solution
A17: 6d | D17: =IF(ISBLANK(INDEX(#REF!,1,1)), "no solution", IF(ISERROR(INDEX(#REF!,1,1)), "error in parsing the solution", INDEX(#REF!,1,1))) -> error in parsing the solution
A18: 7c | D18: =IF(ISBLANK(INDEX(#REF!,1,1)), "no solution", IF(ISERROR(INDEX(#REF!,1,1)), "error in parsing the solution", INDEX(#REF!,1,1))) -> error in parsing the solution
A19: 8a | D19: =IF(ISBLANK(INDEX(#REF!,1,1)), "no solution", IF(ISERROR(INDEX(#REF!,1,1)), "error in parsing the solution", INDEX(#REF!,1,1))) -> error in parsing the solution
A20: 8b | D20: =IF(ISBLANK(INDEX(#REF!,1,1)), "no solution", IF(ISERROR(INDEX(#REF!,1,1)), "error in parsing the solution", INDEX(#REF!,1,1))) -> error in parsing the solution
A21: 8c | D21: =IF(ISBLANK(INDEX(#REF!,1,1)), "no solution", IF(ISERROR(INDEX(#REF!,1,1)), "error in parsing the solution", INDEX(#REF!,1,1))) -> error in parsing the solution
A22: LevelUp1 | D22: =IF(ISBLANK(INDEX('AB Test'!$A$26:$C$27,1,1)), "no solution", IF(ISERROR(INDEX('AB Test'!$A$26:$C$27,1,1)), "error in parsing the solution", INDEX('AB Test'!$A$26:$C$27,1,1))) -> no solution
A23: LevelUp2 | D23: =IF(ISBLANK(INDEX('AB Test'!$A$31:$C$33,1,1)), "no solution", IF(ISERROR(INDEX('AB Test'!$A$31:$C$33,1,1)), "error in parsing the solution", INDEX('AB Test'!$A$31:$C$33,1,1))) -> no solution
A24: LevelUp6 | D24: =IF(ISBLANK(INDEX('AB Test'!$A$49:$C$53,1,1)), "no solution", IF(ISERROR(INDEX('AB Test'!$A$49:$C$53,1,1)), "error in parsing the solution", INDEX('AB Test'!$A$49:$C$53,1,1))) -> no solution
A25: LevelUp7 | D25: =IF(ISBLANK(INDEX('AB Test'!$A$58:$C$62,1,1)), "no solution", IF(ISERROR(INDEX('AB Test'!$A$58:$C$62,1,1)), "error in parsing the solution", INDEX('AB Test'!$A$58:$C$62,1,1))) -> no solution
